Workbook

Sheet Cronograma maestro
A1: Cronograma maestro (también lista de Issues)
A2: Resp.: A / B / C = integrantes del equipo · D1–D7 = día de la semana · Estado: use la lista desplegable
A4: # | B4: Semana | C4: Actividad / Issue | D4: Resp. | E4: Componente | F4: Días | G4: Estado | H4: Notas
A5: Semana 1: Diseño y organización
A6: 1 | B6: Semana 1 | C6: Crear repo, agregar integrantes y dar acceso al docente | D6: A | E6: Gestión | F6: D1 | G6: Pendiente
A7: 2 | B7: Semana 1 | C7: Crear GitHub Project (5 columnas y campos) y los 12+ Issues | D7: A | E7: Gestión | F7: D1–D2 | G7: Pendiente
A8: 3 | B8: Semana 1 | C8: Definir arquitectura de la variante y diagrama | D8: B | E8: Arquitectura | F8: D2–D3 | G8: Pendiente
A9: 4 | B9: Semana 1 | C9: Contrato JSON del evento y ejemplo en samples/ | D9: C | E9: Datos | F9: D2–D3 | G9: Pendiente
A10: 5 | B10: Semana 1 | C10: Definir 3 KPIs (stockouts, picking promedio, pedidos incompletos) | D10: B | E10: KPIs | F10: D3 | G10: Pendiente
A11: 6 | B11: Semana 1 | C11: Definir 2 alertas con umbrales iniciales (stock crítico, picking fuera de tiempo) | D11: C | E11: Alertas | F11: D3 | G11: Pendiente
A12: 7 | B12: Semana 1 | C12: Topic, key y particiones de Kafka con justificación | D12: A | E12: Kafka | F12: D3–D4 | G12: Pendiente
A13: 8 | B13: Semana 1 | C13: Estructura del repo y docker-compose.yml preliminar | D13: A | E13: Infra | F13: D4 | G13: Pendiente
A14: 9 | B14: Semana 1 | C14: README inicial | D14: B | E14: Docs | F14: D4–D5 | G14: Pendiente
A15: 10 | B15: Semana 1 | C15: ADR-001 (key/particiones) | D15: A y C | E15: Docs | F15: D5 | G15: Pendiente
A16: 11 | B16: Semana 1 | C16: semana1.md, revisión cruzada y release v0.1.0-foundation | D16: Todos | E16: Docs | F16: D6–D7 | G16: Pendiente
A17: Semana 2: Pipeline funcional y CI
A18: 12 | B18: Semana 2 | C18: Producer de eventos de inventario y picking, identificables por equipo | D18: A | E18: Producer | F18: D1–D2 | G18: Pendiente
A19: 13 | B19: Semana 2 | C19: Kafka con varias particiones y key implementada en Docker | D19: A | E19: Kafka | F19: D1–D2 | G19: Pendiente
A20: 14 | B20: Semana 2 | C20: Spark Structured Streaming: consumo y parseo de eventos | D20: B | E20: Spark | F20: D2–D3 | G20: Pendiente
A21: 15 | B21: Semana 2 | C21: 3 transformaciones y 1 agregación por ventana (picking promedio por tienda) | D21: B | E21: Spark | F21: D3–D4 | G21: Pendiente
A22: 16 | B22: Semana 2 | C22: Implementar las 2 reglas de alerta | D22: C | E22: Alertas | F22: D3–D4 | G22: Pendiente
A23: 17 | B23: Semana 2 | C23: Persistencia en Parquet con checkpoint (Raw → Processed → Curated) | D23: C | E23: Data Lake | F23: D4–D5 | G23: Pendiente
A24: 18 | B24: Semana 2 | C24: Pruebas en tests/ (contrato del evento y reglas) | D24: C | E24: Pruebas | F24: D4–D5 | G24: Pendiente
A25: 19 | B25: Semana 2 | C25: ci.yml (push, pull_request, workflow_dispatch) | D25: A | E25: CI | F25: D3–D5 | G25: Pendiente
A26: 20 | B26: Semana 2 | C26: Ejecutar, observar valores reales y ajustar umbrales | D26: Todos | E26: Calibración | F26: D5–D6 | G26: Pendiente
A27: 21 | B27: Semana 2 | C27: ADR-002 (decisión basada en la ejecución) y semana2.md | D27: Todos | E27: Docs | F27: D6 | G27: Pendiente
A28: 22 | B28: Semana 2 | C28: Revisión cruzada de PRs y release v0.2.0-streaming | D28: Todos | E28: Release | F28: D7 | G28: Pendiente
A29: Semana 3: Airflow, calidad y resiliencia
A30: 23 | B30: Semana 3 | C30: Airflow en Docker y DAG base con mínimo 5 tasks | D30: A | E30: Airflow | F30: D1–D2 | G30: Pendiente
A31: 24 | B31: Semana 3 | C31: Tasks con dependencias, retries y XCom | D31: B | E31: Airflow | F31: D2–D3 | G31: Pendiente
A32: 25 | B32: Semana 3 | C32: Task de validación de fuentes y calidad (nulos, stock negativo, SKU inválido) | D32: C | E32: Calidad | F32: D2–D4 | G32: Pendiente
A33: 26 | B33: Semana 3 | C33: Task de agregación de KPIs y de reporte de salida | D33: B | E33: KPIs | F33: D3–D4 | G33: Pendiente
A34: 27 | B34: Semana 3 | C34: Fallo controlado y documentación de la recuperación | D34: B y C | E34: Resiliencia | F34: D4–D5 | G34: Pendiente
A35: 28 | B35: Semana 3 | C35: Ampliar CI: importar/validar el DAG y pruebas de reglas de negocio | D35: A | E35: CI | F35: D4–D5 | G35: Pendiente
A36: 29 | B36: Semana 3 | C36: ADR-003 (orquestación/recuperación) y semana3.md con el log real | D36: Todos | E36: Docs | F36: D6 | G36: Pendiente
A37: 30 | B37: Semana 3 | C37: Revisión cruzada y release v0.3.0-orchestration | D37: Todos | E37: Release | F37: D7 | G37: Pendiente
A38: Semana 4: Integración y release final
A39: 31 | B39: Semana 4 | C39: Integrar y estabilizar el pipeline completo (Docker → Kafka → Spark → Lake → Airflow) | D39: Todos | E39: Integración | F39: D1–D3 | G39: Pendiente
A40: 32 | B40: Semana 4 | C40: Quality gate completo en CI y, si se implementa, release.yml | D40: A | E40: CI | F40: D2–D4 | G40: Pendiente
A41: 33 | B41: Semana 4 | C41: Pruebas finales y ajuste final de umbrales | D41: C | E41: Pruebas | F41: D2–D4 | G41: Pendiente
...

Sheet Semana 1
A1: Semana 1: Diseño y organización
A3: # | B3: Actividad / Issue | C3: Resp. | D3: Componente | E3: Días | F3: Estado | G3: Notas
A4: 1 | B4: Crear repo, agregar integrantes y dar acceso al docente | C4: A | D4: Gestión | E4: D1 | F4: Pendiente
A5: 2 | B5: Crear GitHub Project (5 columnas y campos) y los 12+ Issues | C5: A | D5: Gestión | E5: D1–D2 | F5: Pendiente
A6: 3 | B6: Definir arquitectura de la variante y diagrama | C6: B | D6: Arquitectura | E6: D2–D3 | F6: Pendiente
A7: 4 | B7: Contrato JSON del evento y ejemplo en samples/ | C7: C | D7: Datos | E7: D2–D3 | F7: Pendiente
A8: 5 | B8: Definir 3 KPIs (stockouts, picking promedio, pedidos incompletos) | C8: B | D8: KPIs | E8: D3 | F8: Pendiente
A9: 6 | B9: Definir 2 alertas con umbrales iniciales (stock crítico, picking fuera de tiempo) | C9: C | D9: Alertas | E9: D3 | F9: Pendiente
A10: 7 | B10: Topic, key y particiones de Kafka con justificación | C10: A | D10: Kafka | E10: D3–D4 | F10: Pendiente
A11: 8 | B11: Estructura del repo y docker-compose.yml preliminar | C11: A | D11: Infra | E11: D4 | F11: Pendiente
A12: 9 | B12: README inicial | C12: B | D12: Docs | E12: D4–D5 | F12: Pendiente
A13: 10 | B13: ADR-001 (key/particiones) | C13: A y C | D13: Docs | E13: D5 | F13: Pendiente
A14: 11 | B14: semana1.md, revisión cruzada y release v0.1.0-foundation | C14: Todos | D14: Docs | E14: D6–D7 | F14: Pendiente
B16: Avance de la semana | C16: =COUNTIF(F4:F14,"Hecho")/COUNTA(A4:A14) -> 0

Sheet Semana 2
A1: Semana 2: Pipeline funcional y CI
A3: # | B3: Actividad / Issue | C3: Resp. | D3: Componente | E3: Días | F3: Estado | G3: Notas
A4: 12 | B4: Producer de eventos de inventario y picking, identificables por equipo | C4: A | D4: Producer | E4: D1–D2 | F4: Pendiente
A5: 13 | B5: Kafka con varias particiones y key implementada en Docker | C5: A | D5: Kafka | E5: D1–D2 | F5: Pendiente
A6: 14 | B6: Spark Structured Streaming: consumo y parseo de eventos | C6: B | D6: Spark | E6: D2–D3 | F6: Pendiente
A7: 15 | B7: 3 transformaciones y 1 agregación por ventana (picking promedio por tienda) | C7: B | D7: Spark | E7: D3–D4 | F7: Pendiente
A8: 16 | B8: Implementar las 2 reglas de alerta | C8: C | D8: Alertas | E8: D3–D4 | F8: Pendiente
A9: 17 | B9: Persistencia en Parquet con checkpoint (Raw → Processed → Curated) | C9: C | D9: Data Lake | E9: D4–D5 | F9: Pendiente
A10: 18 | B10: Pruebas en tests/ (contrato del evento y reglas) | C10: C | D10: Pruebas | E10: D4–D5 | F10: Pendiente
A11: 19 | B11: ci.yml (push, pull_request, workflow_dispatch) | C11: A | D11: CI | E11: D3–D5 | F11: Pendiente
A12: 20 | B12: Ejecutar, observar valores reales y ajustar umbrales | C12: Todos | D12: Calibración | E12: D5–D6 | F12: Pendiente
A13: 21 | B13: ADR-002 (decisión basada en la ejecución) y semana2.md | C13: Todos | D13: Docs | E13: D6 | F13: Pendiente
A14: 22 | B14: Revisión cruzada de PRs y release v0.2.0-streaming | C14: Todos | D14: Release | E14: D7 | F14: Pendiente
B16: Avance de la semana | C16: =COUNTIF(F4:F14,"Hecho")/COUNTA(A4:A14) -> 0

Sheet Semana 3
A1: Semana 3: Airflow, calidad y resiliencia
A3: # | B3: Actividad / Issue | C3: Resp. | D3: Componente | E3: Días | F3: Estado | G3: Notas
A4: 23 | B4: Airflow en Docker y DAG base con mínimo 5 tasks | C4: A | D4: Airflow | E4: D1–D2 | F4: Pendiente
A5: 24 | B5: Tasks con dependencias, retries y XCom | C5: B | D5: Airflow | E5: D2–D3 | F5: Pendiente
A6: 25 | B6: Task de validación de fuentes y calidad (nulos, stock negativo, SKU inválido) | C6: C | D6: Calidad | E6: D2–D4 | F6: Pendiente
A7: 26 | B7: Task de agregación de KPIs y de reporte de salida | C7: B | D7: KPIs | E7: D3–D4 | F7: Pendiente
A8: 27 | B8: Fallo controlado y documentación de la recuperación | C8: B y C | D8: Resiliencia | E8: D4–D5 | F8: Pendiente
A9: 28 | B9: Ampliar CI: importar/validar el DAG y pruebas de reglas de negocio | C9: A | D9: CI | E9: D4–D5 | F9: Pendiente
A10: 29 | B10: ADR-003 (orquestación/recuperación) y semana3.md con el log real | C10: Todos | D10: Docs | E10: D6 | F10: Pendiente
A11: 30 | B11: Revisión cruzada y release v0.3.0-orchestration | C11: Todos | D11: Release | E11: D7 | F11: Pendiente
B13: Avance de la semana | C13: =COUNTIF(F4:F11,"Hecho")/COUNTA(A4:A11) -> 0

Sheet Semana 4
A1: Semana 4: Integración y release final
A3: # | B3: Actividad / Issue | C3: Resp. | D3: Componente | E3: Días | F3: Estado | G3: Notas
A4: 31 | B4: Integrar y estabilizar el pipeline completo (Docker → Kafka → Spark → Lake → Airflow) | C4: Todos | D4: Integración | E4: D1–D3 | F4: Pendiente
A5: 32 | B5: Quality gate completo en CI y, si se implementa, release.yml | C5: A | D5: CI | E5: D2–D4 | F5: Pendiente
A6: 33 | B6: Pruebas finales y ajuste final de umbrales | C6: C | D6: Pruebas | E6: D2–D4 | F6: Pendiente
A7: 34 | B7: Cerrar o justificar los Issues pendientes y ordenar el Kanban | C7: A | D7: Gestión | E7: D4 | F7: Pendiente
A8: 35 | B8: README final (los 12 puntos obligatorios y tabla de contribuciones) | C8: B | D8: Docs | E8: D3–D5 | F8: Pendiente
A9: 36 | B9: workflow_dispatch: cada integrante lo ejecuta una vez | C9: Todos | D9: CI | E9: D5 | F9: Pendiente
A10: 37 | B10: Guion y ensayo del video | C10: Todos | D10: Video | E10: D5 | F10: Pendiente
A11: 38 | B11: Grabación del video (máx. 10 min) y enlace en el README | C11: Todos | D11: Video | E11: D6 | F11: Pendiente
A12: 39 | B12: CI en verde, tag y GitHub Release v1.0.0 | C12: A | D12: Release | E12: D7 | F12: Pendiente
B14: Avance de la semana | C14: =COUNTIF(F4:F12,"Hecho")/COUNTA(A4:A12) -> 0

Sheet Resumen
A1: Resumen por semana y responsable
A3: Semana | B3: Total | C3: Hechas | D3: % avance | E3: A | F3: B | G3: C | H3: Todos
A4: Semana 1 | B4: =COUNTIF('Cronograma maestro'!$B$5:$B$47,A4) -> 11 | C4: =COUNTIFS('Cronograma maestro'!$B$5:$B$47,A4,'Cronograma maestro'!$G$5:$G$47,"Hecho") -> 0 | D4: =IF(B4=0,0,C4/B4) -> 0 | E4: =COUNTIFS('Cronograma maestro'!$B$5:$B$47,$A4,'Cronograma maestro'!$D$5:$D$47,"*A*") -> 5 | F4: =COUNTIFS('Cronograma maestro'!$B$5:$B$47,$A4,'Cronograma maestro'!$D$5:$D$47,"*B*") -> 3 | G4: =COUNTIFS('Cronograma maestro'!$B$5:$B$47,$A4,'Cronograma maestro'!$D$5:$D$47,"*C*") -> 3 | H4: =COUNTIFS('Cronograma maestro'!$B$5:$B$47,$A4,'Cronograma maestro'!$D$5:$D$47,"Todos") -> 1
A5: Semana 2 | B5: =COUNTIF('Cronograma maestro'!$B$5:$B$47,A5) -> 11 | C5: =COUNTIFS('Cronograma maestro'!$B$5:$B$47,A5,'Cronograma maestro'!$G$5:$G$47,"Hecho") -> 0 | D5: =IF(B5=0,0,C5/B5) -> 0 | E5: =COUNTIFS('Cronograma maestro'!$B$5:$B$47,$A5,'Cronograma maestro'!$D$5:$D$47,"*A*") -> 3 | F5: =COUNTIFS('Cronograma maestro'!$B$5:$B$47,$A5,'Cronograma maestro'!$D$5:$D$47,"*B*") -> 2 | G5: =COUNTIFS('Cronograma maestro'!$B$5:$B$47,$A5,'Cronograma maestro'!$D$5:$D$47,"*C*") -> 3 | H5: =COUNTIFS('Cronograma maestro'!$B$5:$B$47,$A5,'Cronograma maestro'!$D$5:$D$47,"Todos") -> 3
A6: Semana 3 | B6: =COUNTIF('Cronograma maestro'!$B$5:$B$47,A6) -> 8 | C6: =COUNTIFS('Cronograma maestro'!$B$5:$B$47,A6,'Cronograma maestro'!$G$5:$G$47,"Hecho") -> 0 | D6: =IF(B6=0,0,C6/B6) -> 0 | E6: =COUNTIFS('Cronograma maestro'!$B$5:$B$47,$A6,'Cronograma maestro'!$D$5:$D$47,"*A*") -> 2 | F6: =COUNTIFS('Cronograma maestro'!$B$5:$B$47,$A6,'Cronograma maestro'!$D$5:$D$47,"*B*") -> 3 | G6: =COUNTIFS('Cronograma maestro'!$B$5:$B$47,$A6,'Cronograma maestro'!$D$5:$D$47,"*C*") -> 2 | H6: =COUNTIFS('Cronograma maestro'!$B$5:$B$47,$A6,'Cronograma maestro'!$D$5:$D$47,"Todos") -> 2
A7: Semana 4 | B7: =COUNTIF('Cronograma maestro'!$B$5:$B$47,A7) -> 9 | C7: =COUNTIFS('Cronograma maestro'!$B$5:$B$47,A7,'Cronograma maestro'!$G$5:$G$47,"Hecho") -> 0 | D7: =IF(B7=0,0,C7/B7) -> 0 | E7: =COUNTIFS('Cronograma maestro'!$B$5:$B$47,$A7,'Cronograma maestro'!$D$5:$D$47,"*A*") -> 3 | F7: =COUNTIFS('Cronograma maestro'!$B$5:$B$47,$A7,'Cronograma maestro'!$D$5:$D$47,"*B*") -> 1 | G7: =COUNTIFS('Cronograma maestro'!$B$5:$B$47,$A7,'Cronograma maestro'!$D$5:$D$47,"*C*") -> 1 | H7: =COUNTIFS('Cronograma maestro'!$B$5:$B$47,$A7,'Cronograma maestro'!$D$5:$D$47,"Todos") -> 4
A8: Total | B8: =SUM(B4:B7) -> 39 | C8: =SUM(C4:C7) -> 0 | D8: =IF(B8=0,0,C8/B8) -> 0 | E8: =SUM(E4:E7) -> 13 | F8: =SUM(F4:F7) -> 9 | G8: =SUM(G4:G7) -> 9 | H8: =SUM(H4:H7) -> 10
A10: Nota: las columnas A, B y C cuentan también las actividades compartidas (p. ej. 'A y C'); 'Todos' cuenta solo las de todo el equipo.
